Generating LALR tables
Error handling request
Traceback (most recent call last):
  File "/Users/haosutang/anaconda/envs/py35/lib/python3.5/site-packages/aiohttp/server.py", line 266, in start
    yield from self.handle_request(message, payload)
  File "/Users/haosutang/anaconda/envs/py35/lib/python3.5/site-packages/aiohttp/web.py", line 90, in handle_request
    resp = yield from handler(request)
  File "/Users/haosutang/Dropbox/2016Spring/CS_207/group/cs207project/tsdb/tsdb_server.py", line 300, in post_handler
    response = self._upsert_meta(op)
  File "/Users/haosutang/Dropbox/2016Spring/CS_207/group/cs207project/tsdb/tsdb_server.py", line 69, in _upsert_meta
    self.server.db.upsert_meta(op['tid'], op['pk'], op['md'])
  File "/Users/haosutang/Dropbox/2016Spring/CS_207/group/cs207project/tsdb/persistentdb.py", line 246, in upsert_meta
    raise ValueError("TimeSeries with pk: ", pk, " not present in db")
ValueError: ('TimeSeries with pk: ', 1, ' not present in db')
